<mujoco model="point_maze">
	<compiler inertiafromgeom="true" angle="radian" coordinate="local"/>
	<option timestep="0.01" gravity="0 0 0" iterations="20" integrator="Euler"/>
	<default >
		<joint damping="1" limited="false"/>
		<geom friction=".5 .1 .1" density="1000" margin="0.002" condim="1" contype="2" conaffinity="1"/>
	</default>
	<asset >
		<texture type="2d" name="groundplane" builtin="checker" rgb1="0.2 0.3 0.4" rgb2="0.1 0.2 0.3" width="100" height="100"/>
		<texture name="skybox" type="skybox" builtin="gradient" rgb1=".4 .6 .8" rgb2="0 0 0" width="800" height="800" mark="random" markrgb="1 1 1"/>
		<material name="groundplane" texture="groundplane" texrepeat="20 20"/>
		<material name="wall" rgba=".7 .5 .3 1"/>
		<material name="target" rgba=".6 .3 .3 1"/>
	</asset>
	<visual >
		<headlight ambient=".4 .4 .4" diffuse=".8 .8 .8" specular="0.1 0.1 0.1"/>
		<map znear="0.01"/>
		<quality shadowsize="2048"/>
	</visual>
	<worldbody >
		<geom name="ground" size="40 40 0.25" pos="0 0 -0.1" type="plane" contype="1" conaffinity="0" material="groundplane"/>
		<camera name="topview" pos="3.0 3.0 7" fovy="30" xyaxes="1 0 0 0 1 0"/>
		<body name="particle" pos="1.2 1.2 0">
			<geom name="particle_geom" type="sphere" size="0.1" rgba="0.0 0.0 1.0 0.0" contype="1"/>
			<site name="particle_site" pos="0.0 0.0 0" size="0.2" rgba="0.3 0.6 0.3 1"/>
			<joint name="ball_x" type="slide" pos="0 0 0" axis="1 0 0"/>
			<joint name="ball_y" type="slide" pos="0 0 0" axis="0 1 0"/>
		</body>
		<site name="target_site" pos="0.0 0.0 0" size="0.2" material="target"/>
		<geom conaffinity="1" type="box" name="wall_0_0" material="wall" pos="1.0 1.0 0" size="0.5 0.5 0.2"/>
		<geom conaffinity="1" type="box" name="wall_0_1" material="wall" pos="1.0 2.0 0" size="0.5 0.5 0.2"/>
		<geom conaffinity="1" type="box" name="wall_0_2" material="wall" pos="1.0 3.0 0" size="0.5 0.5 0.2"/>
		<geom conaffinity="1" type="box" name="wall_0_3" material="wall" pos="1.0 4.0 0" size="0.5 0.5 0.2"/>
		<geom conaffinity="1" type="box" name="wall_0_4" material="wall" pos="1.0 5.0 0" size="0.5 0.5 0.2"/>
		<geom conaffinity="1" type="box" name="wall_1_0" material="wall" pos="2.0 1.0 0" size="0.5 0.5 0.2"/>
		<geom conaffinity="1" type="box" name="wall_1_4" material="wall" pos="2.0 5.0 0" size="0.5 0.5 0.2"/>
		<geom conaffinity="1" type="box" name="wall_2_0" material="wall" pos="3.0 1.0 0" size="0.5 0.5 0.2"/>
		<geom conaffinity="1" type="box" name="wall_2_1" material="wall" pos="3.0 2.0 0" size="0.5 0.5 0.2"/>
		<geom conaffinity="1" type="box" name="wall_2_2" material="wall" pos="3.0 3.0 0" size="0.5 0.5 0.2"/>
		<geom conaffinity="1" type="box" name="wall_2_4" material="wall" pos="3.0 5.0 0" size="0.5 0.5 0.2"/>
		<geom conaffinity="1" type="box" name="wall_3_0" material="wall" pos="4.0 1.0 0" size="0.5 0.5 0.2"/>
		<geom conaffinity="1" type="box" name="wall_3_4" material="wall" pos="4.0 5.0 0" size="0.5 0.5 0.2"/>
		<geom conaffinity="1" type="box" name="wall_4_0" material="wall" pos="5.0 1.0 0" size="0.5 0.5 0.2"/>
		<geom conaffinity="1" type="box" name="wall_4_1" material="wall" pos="5.0 2.0 0" size="0.5 0.5 0.2"/>
		<geom conaffinity="1" type="box" name="wall_4_2" material="wall" pos="5.0 3.0 0" size="0.5 0.5 0.2"/>
		<geom conaffinity="1" type="box" name="wall_4_3" material="wall" pos="5.0 4.0 0" size="0.5 0.5 0.2"/>
		<geom conaffinity="1" type="box" name="wall_4_4" material="wall" pos="5.0 5.0 0" size="0.5 0.5 0.2"/>
		<geom conaffinity="1" type="box" name="obscure" material="wall" pos="3.0 4.0 0.5" size="0.5 0.5 0.2"/>
	</worldbody>
	<actuator >
		<motor joint="ball_x" ctrlrange="-1.0 1.0" ctrllimited="true" gear="100"/>
		<motor joint="ball_y" ctrlrange="-1.0 1.0" ctrllimited="true" gear="100"/>
	</actuator>
</mujoco>
